package main

import (
	"context"
	"fmt"
	"log"
	"net"
	"net/http"
	"os"
	"os/signal"
	"syscall"
	"time"

	"github.com/dasuken/budougumibon/config"
	"golang.org/x/sync/errgroup"
)

func main() {
	if err := run(context.Background()); err != nil {
		log.Printf("failed to terminate server: %v", err)
	}
}

func run(ctx context.Context) error {
	ctx, stop := signal.NotifyContext(ctx, os.Interrupt, syscall.SIGTERM)
	defer stop()
	cfg, _ := config.New()
	l, err := net.Listen("tcp", fmt.Sprintf(":%d", cfg.Port))
	if err != nil {
		log.Fatalf("failed to listen port %d, err: %v \n", cfg.Port, err)
	}

	url := fmt.Sprintf("http://%s", l.Addr().String())
	log.Printf("start with %s\n", url)

	s := &http.Server{
		Handler: http.HandlerFunc(func(w http.ResponseWriter, r *http.Request) {
			time.Sleep(5 * time.Second)

			fmt.Fprintf(w, "Hello, %s", r.URL.Path[1:])
		}),
	}

	// 引数のcontext使わなかったら、親のcancelが届かない
	eg, ctx := errgroup.WithContext(ctx)
	eg.Go(func() error {
		if err := s.Serve(l); err != nil && err != http.ErrServerClosed {
			log.Printf("failed to close: %+v", err)
			return err
		}

		return nil
	})

	<-ctx.Done()
	// ここでctx渡さないのは何故なのかな
	// Shutdownで即キャンセル関数が走って`context canceledが帰ってくる`
	// shutdownはサーバー内部のコンテキストツリーにキャンセル処理を走らせhttp.ErrServerClosedを送信
	// 尚且つ引数のcontextにcancel処理
	// shutodownは内部実装的にctx.Doneで値を取得するとctx.Errを返し、なければ適当なtimeout(nextPoll)を設定してシャットダウン
	// nextPoll()のtickが具体的にどう決定されるのかはまだ見てない
	if err := s.Shutdown(context.Background()); err != nil {
		log.Println("server shut down")
		return err
	}

	return eg.Wait()
}
